Workbook

Sheet Read Me
A1: Anthropic (ANT) IPO Valuation — Hybrid Business Model
A2: Prepared by Mike Ye | mikeye.com | Version 1.3.1, October 26, 2026 | Reviewed over three rounds with an independent AI audit (Ella) and revised
A4: WHAT THIS IS
A5: A scenario valuation of Anthropic built from its public S-1. It values (1) the business as it exists today, pay-per-token plus subscriptions, and (2) a hybrid that adds a
A6: hypothetical third line where Anthropic takes a cut of measurable value Claude creates for partners. The question: can tokens and subscriptions alone support a $2T valuation?
A7: Reported facts, figures derived from the filing, and hypothetical assumptions are labeled separately.
A9: HOW TO USE IT
A10: Change yellow cells on Inputs and the model recalculates. Input checks at the bottom of Inputs reject invalid entries (negative costs, fractional depreciation lives,
A11: stock comp above personnel); loss-making scenarios are allowed and show 'Not meaningful' instead. The Summary shows the check result in cell A3.
A12: Color code: blue = typed in (reported or assumed); black = formula; green = link to another tab; yellow fill = assumption you can change.
A14: TABS
A15: Summary — results, linked limitations, value-share break-even tests, market check, $2T test, tax sensitivity. Change Log — v1.2 to v1.3 changes and verification table.
... A64: Anthropic has not reviewed or endorsed this model. Do your own research.

Sheet Summary
A1: Anthropic (ANT) — IPO valuation: core business vs. hybrid business model (v1.3.1)
A2: Prepared by Mike Ye, mikeye.com. $ billions except per share. Change yellow cells on Inputs. Not investment advice — see Read Me.
A3: =Inputs!C131 -> All input checks passed
A4: Valuation | B4: Bear | C4: Base | D4: Bull | E4: Weighted
A5: Value per share — hybrid | B5: =Bear!G189 -> 12.973183 | C5: =Base!G189 -> 87.834506 | D5: =Bull!G189 -> 347.32945 | E5: =IF(Inputs!$B$131>0,"check inputs",IF(COUNT(B5:D5)<3,"n/a",SUMPRODUCT(B5:D5,$B$13:$D$13))) -> 133.99291
A6: Value per share — core only (tokens + subscriptions) | B6: =Bear!F189 -> 14.541989 | C6: =Base!F189 -> 76.388093 | D6: =Bull!F189 -> 196.94872 | E6: =IF(Inputs!$B$131>0,"check inputs",IF(COUNT(B6:D6)<3,"n/a",SUMPRODUCT(B6:D6,$B$13:$D$13))) -> 91.066722
A7: Equity value — hybrid ($B) | B7: =IFERROR(Bear!G191/1000,"n/a") -> 232.25449 | C7: =IFERROR(Base!G191/1000,"n/a") -> 1572.4713 | D7: =IFERROR(Bull!G191/1000,"n/a") -> 6598.7198 | E7: =IF(Inputs!$B$131>0,"check inputs",IF(COUNT(B7:D7)<3,"n/a",SUMPRODUCT(B7:D7,$B$13:$D$13))) -> 2493.9792
A8: Equity value — core only ($B) | B8: =IFERROR(Bear!F191/1000,"n/a") -> 260.34029 | C8: =IFERROR(Base!F191/1000,"n/a") -> 1367.5501 | D8: =IFERROR(Bull!F191/1000,"n/a") -> 3668.3525 | E8: =IF(Inputs!$B$131>0,"check inputs",IF(COUNT(B8:D8)<3,"n/a",SUMPRODUCT(B8:D8,$B$13:$D$13))) -> 1665.9482
A9: Hybrid uplift vs. core | B9: =IFERROR(B7/B8-1,"n/a") -> -0.10788113 | C9: =IFERROR(C7/C8-1,"n/a") -> 0.14984552 | D9: =IFERROR(D7/D8-1,"n/a") -> 0.79882381 | E9: =IFERROR(E7/E8-1,"n/a") -> 0.49703285
A10: Funding status (hybrid) | B10: =Bear!G183 -> No raise needed | C10: =Base!G183 -> No raise needed | D10: =Bull!G183 -> No raise needed
A11: Public Benefit issuance steps (hybrid) | B11: =Bear!G188 -> 0 | C11: =Base!G188 -> 0 | D11: =Bull!G188 -> 3
A12: Exit value share of value — P/E / cash flow (hybrid) | B12: =TEXT(Bear!G172,"0%")&" / "&TEXT(Bear!G173,"0%") -> 93% / 88% | C12: =TEXT(Base!G172,"0%")&" / "&TEXT(Base!G173,"0%") -> 93% / 92% | D12: =TEXT(Bull!G172,"0%")&" / "&TEXT(Bull!G173,"0%") -> 94% / 93%
A13: Probability | B13: =Inputs!B93 -> 0.25 | C13: =Inputs!C93 -> 0.5 | D13: =Inputs!D93 -> 0.25 | E13: =SUM($B$13:$D$13) -> 1
A14: Bull case share of weighted hybrid value per share | E14: =IFERROR(D13*D5/E5,"n/a") -> 0.64803699
A16: Headline limitations (linked) | B16: Value
A17: Base hybrid value per share | B17: =C5 -> 87.834506
A18: Combined-stress (S6) hybrid value per share | B18: =S6!G189 -> unresolved
A19: Combined-stress funding status | B19: =S6!G183 -> Not meaningful: 2030 earnings or cash flow negative
A20: Flat-revenue stress (S1): cash at end 2030 and runway | B20: =TEXT(S1!G141/1000,"$0.0")&"B; "&IF(ISNUMBER(S1!G181),TEXT(S1!G181,"0.0")&" years of cash at 2030 burn","cash-positive") -> $12.4B; 0.2 years of cash at 2030 burn
A21: Base: exit value share of value (P/E method / cash flow method) | B21: =C12 -> 93% / 92%
A22: Bull share of weighted value | B22: =E14 -> 0.64803699
A23: Both valuation methods use the same forecasts, so blending them is not independent confirmation. Most value sits in the post-2030 exit value.
A24: ="Assumed, not disclosed: state tax on "&TEXT(Inputs!$B$46,"0%")&" of income at "&TEXT(Inputs!$B$47,"0.0%")&" gives a mature combined rate of "&TEXT(Inputs!$B$43+Inputs!$B$46*Inputs!$B$47*(1-Inputs!$B$43),"0.00%")&". Covenant: $5B minimum liquidity from Q4 2026 (cash used as proxy)." -> Assumed, not disclosed: state tax on 72% of income at 6.0% gives a mature combined rate of 24.41%. Covenant: $5B minimum liquidity from Q4 2026 (cash used as proxy).
A25: 2030 snapshot | B25: Bear | C25: Base | D25: Bull
A26: Core revenue ($B) | B26: =IFERROR(Bear!G5/1000,"n/a") -> 148.48005 | C26: =IFERROR(Base!G5/1000,"n/a") -> 283.68023 | D26: =IFERROR(Bull!G5/1000,"n/a") -> 521.49015
A27: Hybrid total revenue ($B) | B27: =IFERROR(Bear!G105/1000,"n/a") -> 147.73765 | C27: =IFERROR(Base!G105/1000,"n/a") -> 321.97706 | D27: =IFERROR(Bull!G105/1000,"n/a") -> 808.30973
A28: Value-share revenue, gross ($B) | B28: =IFERROR(Bear!G29/1000,"n/a") -> 2.969601 | C28: =IFERROR(Base!G29/1000,"n/a") -> 51.062441 | D28: =IFERROR(Bull!G29/1000,"n/a") -> 312.89409
A29: Core operating margin (after stock comp & depreciation) | B29: =Bear!G54 -> 0.094094487 | C29: =Base!G54 -> 0.30031884 | D29: =Bull!G54 -> 0.40821284
A30: Hybrid operating margin | B30: =Bear!G110 -> 0.07556148 | C30: =Base!G110 -> 0.31006794 | D30: =Bull!G110 -> 0.48419351
A31: Compute % of core revenue | B31: =Bear!G19 -> 0.51550418 | C31: =Base!G19 -> 0.3526967 | D31: =Bull!G19 -> 0.2872467
A32: Effective tax rate (hybrid) | B32: =Bear!G126 -> 0.244128 | C32: =Base!G126 -> 0.244128 | D32: =Bull!G126 -> 0.244128
A33: Value created for partners ($B) | B33: =IFERROR(Bear!G27/1000,"n/a") -> 29.69601 | C33: =IFERROR(Base!G27/1000,"n/a") -> 340.41627 | D33: =IFERROR(Bull!G27/1000,"n/a") -> 1564.4705
A34: Value created as % of $40T knowledge-work pool | B34: =Bear!G36 -> 0.00074240026 | C34: =Base!G36 -> 0.0085104067 | D34: =Bull!G36 -> 0.039111761
A36: Value-share break-even tests (per $1 of revenue moved, 2030 steady state) | B36: Bear | C36: Base | D36: Bull
A37: 1. Operating: contribution per $1 moved | B37: =Inputs!$B$101*Inputs!$B$102*(1-Inputs!$B$104-Inputs!$B$105-Inputs!$B$106)-Inputs!$B$103 -> -0.38 | C37: =Inputs!$C$101*Inputs!$C$102*(1-Inputs!$C$104-Inputs!$C$105-Inputs!$C$106)-Inputs!$C$103 -> 0.36 | D37: =Inputs!$D$101*Inputs!$D$102*(1-Inputs!$D$104-Inputs!$D$105-Inputs!$D$106)-Inputs!$D$103 -> 1.408
A38: 2. Cash: after tax, capex and its depreciation tax shield, per $1 moved (steady state) | B38: =(1-Bear!G126)*(Inputs!$B$101*Inputs!$B$102*(1-Inputs!$B$104-Inputs!$B$105-Inputs!$B$106)-Inputs!$B$103-CHOOSE(Inputs!$B$35,Inputs!$F$55*(Inputs!$B$101*Inputs!$B$102-Inputs!$B$103),Inputs!$B$36*Inputs!$B$101*Inputs!$B$102,0)) -> -0.283452 | C38: =(1-Base!G126)*(Inputs!$C$101*Inputs!$C$102*(1-Inputs!$C$104-Inputs!$C$105-Inputs!$C$106)-Inputs!$C$103-CHOOSE(Inputs!$B$35,Inputs!$F$55*(Inputs!$C$101*Inputs!$C$102-Inputs!$C$103),Inputs!$B$36*Inputs!$C$101*Inputs!$C$102,0)) -> 0.23809968 | D38: =(1-Bull!G126)*(Inputs!$D$101*Inputs!$D$102*(1-Inputs!$D$104-Inputs!$D$105-Inputs!$D$106)-Inputs!$D$103-CHOOSE(Inputs!$B$35,Inputs!$F$55*(Inputs!$D$101*Inputs!$D$102-Inputs!$D$103),Inputs!$B$36*Inputs!$D$101*Inputs!$D$102,0)) -> 0.98112186
A39: 3. Value: hybrid equity less core equity ($B) | B39: =IFERROR(Bear!G191/1000-Bear!F191/1000,"n/a") -> -28.085805 | C39: =IFERROR(Base!G191/1000-Base!F191/1000,"n/a") -> 204.92125 | D39: =IFERROR(Bull!G191/1000-Bull!F191/1000,"n/a") -> 2930.3673
A40: Minimum cut to pass operating test | B40: =IFERROR(Inputs!$B$103/(Inputs!$B$101*(1-Inputs!$B$104-Inputs!$B$105-Inputs!$B$106)),0) -> 0.41666667 | C40: =IFERROR(Inputs!$C$103/(Inputs!$C$101*(1-Inputs!$C$104-Inputs!$C$105-Inputs!$C$106)),0) -> 0.068181818 | D40: =IFERROR(Inputs!$D$103/(Inputs!$D$101*(1-Inputs!$D$104-Inputs!$D$105-Inputs!$D$106)),0) -> 0.024875622
A41: Minimum cut to pass cash test | B41: =IFERROR(CHOOSE(Inputs!$B$35,Inputs!$B$103*(1-Inputs!$F$55)/(Inputs!$B$101*((1-Inputs!$B$104-Inputs!$B$105-Inputs!$B$106)-Inputs!$F$55)),Inputs!$B$103/(Inputs!$B$101*((1-Inputs!$B$104-Inputs!$B$105-Inputs!$B$106)-Inputs!$B$36)),Inputs!$B$103/(Inputs!$B$101*(1-Inputs!$B$104-Inputs!$B$105-Inputs!$B$106))),"n/a") -> 0.475 | C41: =IFERROR(CHOOSE(Inputs!$B$35,Inputs!$C$103*(1-Inputs!$F$55)/(Inputs!$C$101*((1-Inputs!$C$104-Inputs!$C$105-Inputs!$C$106)-Inputs!$F$55)),Inputs!$C$103/(Inputs!$C$101*((1-Inputs!$C$104-Inputs!$C$105-Inputs!$C$106)-Inputs!$B$36)),Inputs!$C$103/(Inputs!$C$101*(1-Inputs!$C$104-Inputs!$C$105-Inputs!$C$106))),"n/a") -> 0.07125 | D41: =IFERROR(CHOOSE(Inputs!$B$35,Inputs!$D$103*(1-Inputs!$F$55)/(Inputs!$D$101*((1-Inputs!$D$104-Inputs!$D$105-Inputs!$D$106)-Inputs!$F$55)),Inputs!$D$103/(Inputs!$D$101*((1-Inputs!$D$104-Inputs!$D$105-Inputs!$D$106)-Inputs!$B$36)),Inputs!$D$103/(Inputs!$D$101*(1-Inputs!$D$104-Inputs!$D$105-Inputs!$D$106))),"n/a") -> 0.025537634
A42: Cut assumed | B42: =Inputs!$B$102 -> 0.1 | C42: =Inputs!$C$102 -> 0.15 | D42: =Inputs!$D$102 -> 0.2
...

Sheet Change Log
A1: Change log: v1.2 to v1.3, plus the v1.3.1 patch
A2: v1.1 and v1.2 are preserved as separate files. Cell references point to the Base tab unless noted; the same rows exist on every case tab.
A4: v1.3.1 patch (narrow; no commercial assumptions changed) | B4: Where
A5: Start-of-year payments now discounted from the start of their year: removes a ~$21.4B overstatement of the $200B S7 prepayment's present value (once, in the shared cash flows) | B5: Base!F167:G167
A6: Funded-path interest now earned on the funded balance after start-of-year payments (S7 2027: zero, since the payment consumes opening cash plus proceeds); taxes reconciled | B6: Base!C154:G155
A7: Default shortfall threshold set to an assumed $5B operating cash buffer ($0 kept as a sensitivity row); the $5B covenant check stays separate | B7: Inputs!B29; Base!G147
A8: Summary title updated to v1.3.1 | B8: Summary!A1
A10: 1. Source corrections | B10: Where
A11: Q2 2026 stock comp: $1,261M from the non-GAAP reconciliation replaces the rounded $1.3B. Lowers the H2 2026 stock comp ratio and end-2026 cash by ~$0.1B | B11: Historicals!G19
A12: Broadcom equipment leases identified as finance leases (~$161.2B rent, 5 years, quarterly from ready-for-service); payment timing still incomplete | B12: Read Me method 4
A13: $5.0B minimum-liquidity covenant (A&R Credit Agreement, quarter-ends from Q4 2026) added as a separate check from the cash-shortfall threshold; definition not in the S-1 | B13: Inputs!B38; Base!C144:G144
A15: 2. Formula corrections | B15: Where
A16: Depreciation now by vintage: each year's capex is depreciated only within its useful life (fixes lives under 5 years) | B16: Base!C52:G52, C108:G108
A17: Funding need uses the lowest cash in each year, including start-of-year payments, not just year-end balances | B17: Base!C142:G146
... A30: No Bear, Base or Bull commercial assumption changed | B30: —
A32: Verification (LibreOffice recalculation) | B32: Expected | C32: Result | D32: Status
A33: S7 funded value per share, base discount (Ella: ~$83.97 at $0 buffer; ~$83.89 at the $5B buffer) | B33: ~$83.9 | C33: =S7!G185 -> 83.913807 | D33: =IF(AND(C33>83.5,C33<84.1),"Pass","Review") -> Pass
A34: S7 peak funding need with $5B buffer ($B) (Ella: ~$64.68B) | B34: ~64.68 | C34: =S7!G146/1000 -> 64.682089 | D34: =IF(ABS(C34-64.68)<0.05,"Pass","Review") -> Pass
A35: S7 peak need with $0 buffer ($B) (Ella: $59.68B) | B35: 59.68 | C35: =S7!G147/1000 -> 59.682089 | D35: =IF(ABS(C35-59.68)<0.05,"Pass","Review") -> Pass
A36: S7 2027 interest change on funded path ($B) | B36: 0 at $0 buffer | C36: =S7!D154/1000 -> 0.125 | D36: =IF(C36>=0,"Info","Review") -> Info
A37: Base hybrid value per share (v1.2: $87.84; change from Q2 stock comp only) | B37: ~$87.84 | C37: =Summary!C5 -> 87.834506 | D37: =IF(ABS(C37-87.84)<0.05,"Pass","Review") -> Pass
A38: Base core value per share (v1.2: $76.40) | B38: ~$76.40 | C38: =Summary!C6 -> 76.388093 | D38: =IF(ABS(C38-76.4)<0.05,"Pass","Review") -> Pass
A39: Weighted hybrid value per share (v1.2: $134.00) | B39: ~$134.00 | C39: =Summary!E5 -> 133.99291 | D39: =IF(ABS(C39-134)<0.1,"Pass","Review") -> Pass
A40: S2 hybrid value per share (Ella checkpoint $70.46) | B40: $70.46 | C40: =S2!G189 -> 70.455706 | D40: =IF(ABS(C40-70.46)<0.01,"Pass","Review") -> Pass
A41: S2 2030 compute vs Base | B41: +20.0% | C41: =S2!G10/Base!G10-1 -> 0.2 | D41: =IF(ABS(C41-0.2)<0.0001,"Pass","Review") -> Pass
A42: S2 2026 compute equals Base | B42: equal | C42: =S2!C10-Base!C10 -> 0 | D42: =IF(C42=0,"Pass","Review") -> Pass
A43: S7 peak need at start of 2027 = $200B less opening cash + $5B buffer ($B) | B43: ~64.7 | C43: =S7!G146/1000 -> 64.682089 | D43: =IF(ABS(C43-(205-S7!D136/1000))<0.01,"Pass","Review") -> Pass
A44: S7 funded path never below threshold | B44: Yes | C44: =COUNTIF(S7!C158:G158,"No") -> 0 | D44: =IF(C44=0,"Pass","Review") -> Pass
A45: S7 prepaid fully credited by 2030 (closing balance, $B) | B45: 0 | C45: =S7!G46/1000 -> 0 | D45: =IF(ABS(C45)<0.001,"Pass","Review") -> Pass
A46: S7 2028 credits capped at eligible compute ($B) | B46: equals 2028 compute | C46: =S7!E45/1000-S7!E44/1000 -> 0 | D46: =IF(ABS(C46)<0.001,"Pass","Review") -> Pass
A47: Zero value-share adoption: hybrid less core equity, Bear/Base/Bull ($B) | B47: 0 / 0 / 0 | C47: 0.0 / 0.0 / 0.0 | D47: Pass
A48: Vintage depreciation vs independent calculation, lives 1 / 2 / 3 / 5 (max difference) | B48: 0 | C48: 0e+00 / 0e+00 / 9e-13 / 1e-13 | D48: Pass
A49: Base hybrid per share at lives 1 / 2 / 3 / 5 | B49: — | C49: $85.9 / $86.34 / $86.78 / $87.83 | D49: Info
A50: Fractional depreciation life (2.5) | B50: warning | C50: CHECK INPUTS: results may be invalid | D50: Pass
A51: Negative cost ratio input | B51: warning; weighted blocked | C51: CHECK INPUTS: results may be invalid; check inputs | D51: Pass
A52: Stock comp above personnel | B52: warning | C52: CHECK INPUTS: results may be invalid | D52: Pass
A53: Legitimate loss scenario (2027 growth -30%) | B53: no warning; 'Not meaningful' | C53: All input checks passed; Not meaningful: 2030 earnings or cash flow negative | D53: Pass
A54: S7 funded value per share at 0% / 15% / 30% discount | B54: decreasing | C54: $84.54 / $83.91 / $83.04 | D54: Pass
A56: Static rows were measured by recalculating copies of v1.3 with the stated inputs; live rows recalculate with the workbook.
A57: S7 note: the raise is sized to the assumed $5B operating cash buffer, so the funded start-of-year low is $5B. The $5B covenant check remains separate because its liquidity definition may differ from cash.
...

Sheet Historicals
A1: Historical financials from the S-1 ($ millions)
A2: Source: Anthropic, PBC Form S-1, filed Oct 26, 2026 (SEC EDGAR CIK 2130357). Blue = reported figure. Black = formula.
A4: Quarterly income statement | B4: Q1 2025 | C4: Q2 2025 | D4: Q3 2025 | E4: Q4 2025 | F4: Q1 2026 | G4: Q2 2026 | H4: Q3 2026 (implied)
A5: Revenue | B5: 376 | C5: 787 | D5: 1382 | E5: 2040 | F5: 4731 | G5: 11555 | H5: =B66*B67 -> 16942
A6: Compute and infrastructure | B6: 944 | C6: 1390 | D6: 2047 | E6: 2945 | F6: 3387 | G6: 5558
A7: Personnel (incl. stock comp) | B7: 218 | C7: 320 | D7: 489 | E7: 812 | F7: 1295 | G7: 1857
A8: Bartz settlement (one-time) | B8: 0 | C8: 0 | D8: 1500 | E8: 0 | F8: 0 | G8: 0
A9: Sales, marketing, and partnerships | B9: 24 | C9: 96 | D9: 202 | E9: 246 | F9: 1033 | G9: 2135
A10: Other operating and administrative | B10: 125 | C10: 181 | D10: 233 | E10: 873 | F10: 683 | G10: 1031
A11: Total operating expenses | B11: =SUM(B6:B10) -> 1311 | C11: =SUM(C6:C10) -> 1987 | D11: =SUM(D6:D10) -> 4471 | E11: =SUM(E6:E10) -> 4876 | F11: =SUM(F6:F10) -> 6398 | G11: =SUM(G6:G10) -> 10581
A12: Operating income (loss) | B12: =B5-B11 -> -935 | C12: =C5-C11 -> -1200 | D12: =D5-D11 -> -3089 | E12: =E5-E11 -> -2836 | F12: =F5-F11 -> -1667 | G12: =G5-G11 -> 974
A13: Interest income | B13: 51 | C13: 64 | D13: 124 | E13: 192 | F13: 349 | G13: 762
A14: Change in fair value of convertible notes etc. (non-cash) | B14: -5701 | C14: -5241 | D14: -9165 | E14: -14201 | F14: -12791 | G14: -59597
A15: Other income (expense), net | B15: 0 | C15: 0 | D15: -3 | E15: -5 | F15: -309 | G15: -8448
A16: Loss before income taxes | B16: =B12+B13+B14+B15 -> -6585 | C16: =C12+C13+C14+C15 -> -6377 | D16: =D12+D13+D14+D15 -> -12133 | E16: =E12+E13+E14+E15 -> -16850 | F16: =F12+F13+F14+F15 -> -14418 | G16: =G12+G13+G14+G15 -> -66309
A17: Provision for income taxes | B17: 7 | C17: 0 | D17: 5 | E17: 8 | F17: 21 | G17: 0
A18: Net income (loss) | B18: =B16-B17 -> -6592 | C18: =C16-C17 -> -6377 | D18: =D16-D17 -> -12138 | E18: =E16-E17 -> -16858 | F18: =F16-F17 -> -14439 | G18: =G16-G17 -> -66309
A19: Stock-based compensation (non-GAAP reconciliation) | B19: 105 | C19: 181 | D19: 305 | E19: 574 | F19: 924 | G19: 1261
A20: Operating income before stock comp | B20: =B12+B19 -> -830 | C20: =C12+C19 -> -1019 | D20: =D12+D19 -> -2784 | E20: =E12+E19 -> -2262 | F20: =F12+F19 -> -743 | G20: =G12+G19 -> 2235
A22: Quarterly ratios
A23: Compute % of revenue | B23: =IFERROR(B6/B5,0) -> 2.5106383 | C23: =IFERROR(C6/C5,0) -> 1.7662008 | D23: =IFERROR(D6/D5,0) -> 1.4811867 | E23: =IFERROR(E6/E5,0) -> 1.4436275 | F23: =IFERROR(F6/F5,0) -> 0.7159163 | G23: =IFERROR(G6/G5,0) -> 0.48100389
A24: Personnel % of revenue | B24: =IFERROR(B7/B5,0) -> 0.57978723 | C24: =IFERROR(C7/C5,0) -> 0.40660737 | D24: =IFERROR(D7/D5,0) -> 0.35383502 | E24: =IFERROR(E7/E5,0) -> 0.39803922 | F24: =IFERROR(F7/F5,0) -> 0.27372648 | G24: =IFERROR(G7/G5,0) -> 0.16070965
A25: Sales, marketing & partnerships % of revenue | B25: =IFERROR(B9/B5,0) -> 0.063829787 | C25: =IFERROR(C9/C5,0) -> 0.12198221 | D25: =IFERROR(D9/D5,0) -> 0.14616498 | E25: =IFERROR(E9/E5,0) -> 0.12058824 | F25: =IFERROR(F9/F5,0) -> 0.21834707 | G25: =IFERROR(G9/G5,0) -> 0.1847685
A26: Other opex % of revenue | B26: =IFERROR(B10/B5,0) -> 0.33244681 | C26: =IFERROR(C10/C5,0) -> 0.22998729 | D26: =IFERROR(D10/D5,0) -> 0.16859624 | E26: =IFERROR(E10/E5,0) -> 0.42794118 | F26: =IFERROR(F10/F5,0) -> 0.14436694 | G26: =IFERROR(G10/G5,0) -> 0.089225444
A27: Operating margin | B27: =IFERROR(B12/B5,0) -> -2.4867021 | C27: =IFERROR(C12/C5,0) -> -1.5247776 | D27: =IFERROR(D12/D5,0) -> -2.2351664 | E27: =IFERROR(E12/E5,0) -> -1.3901961 | F27: =IFERROR(F12/F5,0) -> -0.3523568 | G27: =IFERROR(G12/G5,0) -> 0.084292514
A28: Operating margin before stock comp | B28: =IFERROR(B20/B5,0) -> -2.2074468 | C28: =IFERROR(C20/C5,0) -> -1.2947903 | D28: =IFERROR(D20/D5,0) -> -2.0144718 | E28: =IFERROR(E20/E5,0) -> -1.1088235 | F28: =IFERROR(F20/F5,0) -> -0.15704925 | G28: =IFERROR(G20/G5,0) -> 0.19342276
A29: Stock comp % of revenue | B29: =IFERROR(B19/B5,0) -> 0.27925532 | C29: =IFERROR(C19/C5,0) -> 0.22998729 | D29: =IFERROR(D19/D5,0) -> 0.22069465 | E29: =IFERROR(E19/E5,0) -> 0.28137255 | F29: =IFERROR(F19/F5,0) -> 0.19530755 | G29: =IFERROR(G19/G5,0) -> 0.10913025
A30: Revenue growth vs prior quarter | C30: =IFERROR(C5/B5-1,0) -> 1.0930851 | D30: =IFERROR(D5/C5-1,0) -> 0.75603558 | E30: =IFERROR(E5/D5-1,0) -> 0.47612156 | F30: =IFERROR(F5/E5-1,0) -> 1.3191176 | G30: =IFERROR(G5/F5-1,0) -> 1.4424012 | H30: =IFERROR(H5/G5-1,0) -> 0.46620511
A31: Revenue added vs prior quarter ($mm) | C31: =C5-B5 -> 411 | D31: =D5-C5 -> 595 | E31: =E5-D5 -> 658 | F31: =F5-E5 -> 2691 | G31: =G5-F5 -> 6824 | H31: =H5-G5 -> 5387
A32: Check: Q1+Q2 2026 revenue less H1 2026 (should be 0) | G32: =F5+G5-F35 -> 0
A33: Check: 2025 quarters less 2025 revenue (should be 0) | G33: =B5+C5+D5+E5-D35 -> 0
A34: Annual & half-year income statement | B34: 2023 | C34: 2024 | D34: 2025 | E34: H1 2025 | F34: H1 2026
A35: Revenue | B35: 41 | C35: 386 | D35: 4585 | E35: 1163 | F35: 16286
A36: Compute and infrastructure | B36: 433 | C36: 2522 | D36: 7326 | E36: 2334 | F36: 8945
A37: Personnel (incl. stock comp) | B37: 95 | C37: 454 | D37: 1839 | E37: 538 | F37: 3152
A38: Bartz settlement (one-time) | B38: 0 | C38: 0 | D38: 1500 | E38: 0 | F38: 0
A39: Sales, marketing, and partnerships | B39: 2 | C39: 43 | D39: 568 | E39: 120 | F39: 3168
A40: Other operating and administrative | B40: 62 | C40: 347 | D40: 1412 | E40: 306 | F40: 1714
A41: Total operating expenses | B41: =SUM(B36:B40) -> 592 | C41: =SUM(C36:C40) -> 3366 | D41: =SUM(D36:D40) -> 12645 | E41: =SUM(E36:E40) -> 3298 | F41: =SUM(F36:F40) -> 16979
A42: Operating income (loss) | B42: =B35-B41 -> -551 | C42: =C35-C41 -> -2980 | D42: =D35-D41 -> -8060 | E42: =E35-E41 -> -2135 | F42: =F35-F41 -> -693
...

Sheet Inputs
A1: Assumptions
A2: Blue = input. Yellow = key assumption you can change. Green = link to another tab. Black = formula. Input checks are at the bottom of this tab.
A4: Shared settings | B4: Value | C4: Note
A5: Q3 2026 revenue (implied, $mm) | B5: =Historicals!H5 -> 16942 | C5: S-1: Q3 2026 revenue was 86x Q4 2024 ($197M). Company separately told investors $16.8B
A6: Cash, equivalents & short-term investments, Jun 30, 2026 ($mm) | B6: =Historicals!B69 -> 131651 | C6: S-1 balance sheet
A7: Initial Public Benefit Fund issuance (shares) | B7: 846840960 | C7: S-1: 846,840,960 Class N shares contributed to the Anthropic Public Benefit Fund (Oct 2026)
A8: Issuance as % of June 30 fully diluted shares | B8: 0.05 | C8: S-1: 5% of fully diluted shares as of June 30, 2026, assuming full conversion of the Amazon notes
A9: June 30, 2026 fully diluted shares (mm) | B9: =B7/B8/1000000 -> 16936.819 | C9: Derived. Assumes this count includes options and RSUs outstanding at June 30 (definition not stated in the S-1). Excludes the Fund issuance
A10: Count the Fund issuance in economic shares? (1 = yes) | B10: 1 | C10: Held by a wholly owned subsidiary, so not outstanding for accounting; may be donated or sold, so counted as economic dilution
A11: RSUs granted after June 30, 2026 (mm) | B11: 91 | C11: S-1 Note 17: ~91M RSUs, grant-date fair value $5.8B, vest over 4 years; performance condition met at IPO
A12: Count post-June RSUs in economic shares? (1 = yes) | B12: 1 | C12: Counted as granted awards. Partial overlap: their future expense is also inside forecast stock comp
A13: October 2026 donation-matching shares (mm) | B13: 28 | C13: S-1 Note 17: ~28.0M Class N shares issued to settle the Q3 2026 donation-matching obligation
A14: RSU shares withheld for taxes at IPO (mm) | B14: 0 | C14: Blank in S-1. Net settlement reduces shares but costs cash (see next rows)
A15: Primary IPO proceeds to company ($mm) | B15: 0 | C15: Blank in S-1. Update from price-range amendment
A16: New shares issued in IPO (mm) | B16: 0 | C16: Blank in S-1. Update from price-range amendment
A17: Cash paid for RSU tax withholding at IPO ($mm) | B17: 0 | C17: Blank in S-1. Paid from IPO proceeds per S-1 use of proceeds; separate from the tax deduction
A18: Economic shares at valuation date (mm) | B18: =B9+B10*B7/1000000+B12*B11+B13-B14+B16 -> 17902.66 | C18: June fully diluted + Fund issuance + post-June RSUs + donation shares - shares withheld + IPO shares
A19: Discount rate | B19: 0.12 | C19: Annual return required on the equity
A20: Interest yield on cash | B20: 0.025 | C20: Q2 2026 actual ~2.3% a year. Applied to opening cash each year; no interest on a negative balance
A21: Weight on P/E method (rest on cash flow method) | B21: 0.5 | C21: Both methods use the same forecasts, so the blend is not independent confirmation
A22: Reference IPO valuation ($mm) | B22: 1500000 | C22: Low end of reported $1.5T-$2T range; sets the Public Benefit step starting price
A23: Reference IPO price per share | B23: =B22/B18 -> 83.786431 | C23: Derived on economic shares
A24: Board issues maximum Public Benefit shares? (1 = yes) | B24: 1 | C24: S-1: discretionary. Model assumes maximum issuance (conservative)
A25: Public Benefit issuance per step (% of shares) | B25: 0.02 | C25: S-1: up to an additional 2% each time the price rises 50% above the prior step
A26: Share price rise per step | B26: 0.5 | C26: S-1: a step requires a close above the threshold on 90 of 120 trading days and a 10-day average above it
A27: Global knowledge-work value pool ($mm) | B27: 40000000 | C27: S-1: knowledge work was more than $40 trillion of economic value in 2025. Sanity check only
A28: Target valuation for the $2T test ($mm) | B28: 2000000 | C28: Used on Summary
A29: Operating cash buffer (shortfall threshold, $mm) | B29: 5000 | C29: Assumed buffer; cash below it is a shortfall. Separate from the $5B liquidity covenant, whose definition may differ from cash. $0 shown as a sensitivity
A30: Equity issuance discount if funding is needed | B30: 0.15 | C30: Illustrative modeling assumption, not observed terms. 0% and 30% shown alongside
A31: Equity issuance fees | B31: 0.03 | C31: Illustrative
A32: Depreciation life of owned capacity (years) | B32: 5 | C32: Straight-line depreciation on capital spending from 2027
A33: Working capital change, % of revenue increase | B33: 0 | C33: H1 2026 working capital was a $1.17B inflow; default 0
A34: Value-share days to collect | B34: 0 | C34: Default 0 reproduces v1.1. Raising it delays value-share cash
A35: Value-share capex basis (1, 2 or 3) | B35: 1 | C35: 1 = company capex rate x net new revenue (v1.1 method); 2 = % of gross value-share revenue; 3 = none (capacity bought via extra-compute charge)
... A40: Years over which prepaid credits are scheduled (from 2028) | B40: 3 | C40: Scheduled credits accumulate; actual credits are capped by eligible charges and the remaining balance
A42: Taxes | B42: Value | C42: Note
A43: Federal tax rate | B43: 0.21 | C43: US federal statutory rate
A44: Federal NOL carryforward at Dec 31, 2025 ($mm) | B44: 8200 | C44: S-1 income tax note: $8.2B, does not expire
A45: Federal NOL usage limit (% of taxable income) | B45: 0.8 | C45: Post-2017 federal NOLs offset up to 80% of taxable income
A46: Share of taxable income subject to state tax | B46: 0.72 | C46: Assumption. Proxy: US share of H1 2026 revenue (72%). Not company disclosure
...

Sheet Bear
A1: Bear — projections, cash and valuation ($ millions except per share)
A2: 2026E = H1 2026 actual + Q3 2026 implied + assumed Q4. Compute is forecast as cash spending (hosting, leases and owned capacity all treated as paid when expensed); the S-1 gives no payment schedule.
A4: Core business: income statement | B4: 2025A | C4: 2026E | D4: 2027E | E4: 2028E | F4: 2029E | G4: 2030E
A5: Revenue | B5: =Historicals!D35 -> 4585 | C5: =Historicals!F35+(Inputs!$B$5+Inputs!$B$60) -> 51728 | D5: =C5*(1+Inputs!$B$62) -> 82764.8 | E5: =D5*(1+Inputs!$B$63) -> 107594.24 | F5: =E5*(1+Inputs!$B$64) -> 129113.09 | G5: =F5*(1+Inputs!$B$65) -> 148480.05
A6: Growth | C6: =IFERROR(C5/B5-1,0) -> 10.282007 | D6: =IFERROR(D5/C5-1,0) -> 0.6 | E6: =IFERROR(E5/D5-1,0) -> 0.3 | F6: =IFERROR(F5/E5-1,0) -> 0.2 | G6: =IFERROR(G5/F5-1,0) -> 0.15
A7: Subscription revenue | B7: =Historicals!D51 -> 789 | C7: =Historicals!F51+(Inputs!$B$5+Inputs!$B$60)*Historicals!F51/Historicals!F35 -> 10233.797 | D7: =D5*Inputs!$B$61 -> 18208.256 | E7: =E5*Inputs!$B$61 -> 23670.733 | F7: =F5*Inputs!$B$61 -> 28404.879 | G7: =G5*Inputs!$B$61 -> 32665.611
A8: Consumption revenue | B8: =B5-B7 -> 3796 | C8: =C5-C7 -> 41494.203 | D8: =D5-D7 -> 64556.544 | E8: =E5-E7 -> 83923.507 | F8: =F5-F7 -> 100708.21 | G8: =G5-G7 -> 115814.44
A10: Compute and infrastructure | B10: =Historicals!D36 -> 7326 | C10: =Historicals!F36+(Inputs!$B$5+Inputs!$B$60)*Inputs!$B$66 -> 26666 | D10: =C10*(1+Inputs!$B$67) -> 42665.6 | E10: =D10*(1+Inputs!$B$68) -> 55465.28 | F10: =E10*(1+Inputs!$B$69) -> 66558.336 | G10: =F10*(1+Inputs!$B$70) -> 76542.086
A11: Personnel (incl. stock comp) | B11: =Historicals!D37 -> 1839 | C11: =Historicals!F37+(Inputs!$B$5+Inputs!$B$60)*Historicals!G24 -> 8847.8714 | D11: =D5*Inputs!$B$71 -> 13242.368 | E11: =E5*Inputs!$B$72 -> 16139.136 | F11: =F5*Inputs!$B$73 -> 18075.832 | G11: =G5*Inputs!$B$74 -> 19302.407
A12: of which stock comp | B12: =Historicals!D49 -> 1158 | C12: =Historicals!F49+(Inputs!$B$5+Inputs!$B$60)*Historicals!G29 -> 6052.7942 | D12: =D5*Inputs!$B$75 -> 8276.48 | E12: =E5*Inputs!$B$76 -> 9683.4816 | F12: =F5*Inputs!$B$77 -> 10329.047 | G12: =G5*Inputs!$B$78 -> 10393.604
A13: Sales, marketing & partner fees | B13: =Historicals!D39 -> 568 | C13: =Historicals!F39+(Inputs!$B$5+Inputs!$B$60)*Historicals!G25 -> 9716.5651 | D13: =D5*Inputs!$B$79 -> 14897.664 | E13: =E5*Inputs!$B$80 -> 18291.021 | F13: =F5*Inputs!$B$81 -> 20658.094 | G13: =G5*Inputs!$B$82 -> 23756.808
A14: Other operating & administrative | B14: =Historicals!D40 -> 1412 | C14: =Historicals!F40+(Inputs!$B$5+Inputs!$B$60)*Historicals!G26 -> 4876.3282 | D14: =D5*Inputs!$B$83 -> 7448.832 | E14: =E5*Inputs!$B$84 -> 8607.5392 | F14: =F5*Inputs!$B$85 -> 9037.9162 | G14: =G5*Inputs!$B$86 -> 10393.604
A15: One-time items (2025 Bartz settlement; 2026 Q3 donation-matching charge) | B15: =Historicals!D38 -> 1500 | C15: =Inputs!$B$37 -> 2000 | D15: 0 | E15: 0 | F15: 0 | G15: 0
A16: Total operating expenses | B16: =B10+B11+B13+B14+B15 -> 12645 | C16: =C10+C11+C13+C14+C15 -> 52106.765 | D16: =D10+D11+D13+D14+D15 -> 78254.464 | E16: =E10+E11+E13+E14+E15 -> 98502.976 | F16: =F10+F11+F13+F14+F15 -> 114330.18 | G16: =G10+G11+G13+G14+G15 -> 129994.9
A17: Operating income before depreciation of new owned capacity | B17: =B5-B16 -> -8060 | C17: =C5-C16 -> -378.76469 | D17: =D5-D16 -> 4510.336 | E17: =E5-E16 -> 9091.264 | F17: =F5-F16 -> 14782.909 | G17: =G5-G16 -> 18485.146
A18: Margin | B18: =IFERROR(B17/B5,0) -> -1.7579062 | C18: =IFERROR(C17/C5,0) -> -0.0073222373 | D18: =IFERROR(D17/D5,0) -> 0.054495824 | E18: =IFERROR(E17/E5,0) -> 0.084495824 | F18: =IFERROR(F17/F5,0) -> 0.11449582 | G18: =IFERROR(G17/G5,0) -> 0.12449582
A19: Compute % of revenue | B19: =IFERROR(B10/B5,0) -> 1.597819 | C19: =IFERROR(C10/C5,0) -> 0.51550418 | D19: =IFERROR(D10/D5,0) -> 0.51550418 | E19: =IFERROR(E10/E5,0) -> 0.51550418 | F19: =IFERROR(F10/F5,0) -> 0.51550418 | G19: =IFERROR(G10/G5,0) -> 0.51550418
A20: Non-cash donation-matching charges (incl. in costs above) | C20: =Historicals!$B$78+Inputs!$B$37 -> 2126 | D20: 0 | E20: 0 | F20: 0 | G20: 0
A21: Discount factor to end 2026 | D21: =1/(1+Inputs!$B$19+Inputs!$B$89)^1 -> 0.89285714 | E21: =1/(1+Inputs!$B$19+Inputs!$B$89)^2 -> 0.79719388 | F21: =1/(1+Inputs!$B$19+Inputs!$B$89)^3 -> 0.71178025 | G21: =1/(1+Inputs!$B$19+Inputs!$B$89)^4 -> 0.63551808
A23: Third business line: value-share partnerships (hypothetical)
A24: Share of core revenue base under value-share | C24: 0 | D24: =Inputs!$B$97 -> 0.005 | E24: =Inputs!$B$98 -> 0.015 | F24: =Inputs!$B$99 -> 0.03 | G24: =Inputs!$B$100 -> 0.05
A25: Revenue base moved to value-share | C25: =C5*C24 -> 0 | D25: =D5*D24 -> 413.824 | E25: =E5*E24 -> 1613.9136 | F25: =F5*F24 -> 3873.3926 | G25: =G5*G24 -> 7424.0026
A26: Value created per $1 of Claude spend | C26: =Inputs!$B$101 -> 4 | D26: =Inputs!$B$101 -> 4 | E26: =Inputs!$B$101 -> 4 | F26: =Inputs!$B$101 -> 4 | G26: =Inputs!$B$101 -> 4
A27: Economic value created for partners | C27: =C25*C26 -> 0 | D27: =D25*D26 -> 1655.296 | E27: =E25*E26 -> 6455.6544 | F27: =F25*F26 -> 15493.571 | G27: =G25*G26 -> 29696.01
A28: Anthropic's cut | C28: =Inputs!$B$102 -> 0.1 | D28: =Inputs!$B$102 -> 0.1 | E28: =Inputs!$B$102 -> 0.1 | F28: =Inputs!$B$102 -> 0.1 | G28: =Inputs!$B$102 -> 0.1
A29: Value-share revenue (gross) | C29: =C27*C28 -> 0 | D29: =D27*D28 -> 165.5296 | E29: =E27*E28 -> 645.56544 | F29: =F27*F28 -> 1549.3571 | G29: =G27*G28 -> 2969.601
A30: Token revenue given up | C30: =C25*Inputs!$B$103 -> 0 | D30: =D25*Inputs!$B$103 -> 206.912 | E30: =E25*Inputs!$B$103 -> 806.9568 | F30: =F25*Inputs!$B$103 -> 1936.6963 | G30: =G25*Inputs!$B$103 -> 3712.0013
A31: Net new revenue | C31: =C29-C30 -> 0 | D31: =D29-D30 -> -41.3824 | E31: =E29-E30 -> -161.39136 | F31: =F29-F30 -> -387.33926 | G31: =G29-G30 -> -742.40026
A32: Delivery cost | C32: =C29*Inputs!$B$104 -> 0 | D32: =D29*Inputs!$B$104 -> 49.65888 | E32: =E29*Inputs!$B$104 -> 193.66963 | F32: =F29*Inputs!$B$104 -> 464.80712 | G32: =G29*Inputs!$B$104 -> 890.88031
A33: Extra compute | C33: =C29*Inputs!$B$105 -> 0 | D33: =D29*Inputs!$B$105 -> 41.3824 | E33: =E29*Inputs!$B$105 -> 161.39136 | F33: =F29*Inputs!$B$105 -> 387.33926 | G33: =G29*Inputs!$B$105 -> 742.40026
A34: Selling, partner fees & overhead | C34: =C29*Inputs!$B$106 -> 0 | D34: =D29*Inputs!$B$106 -> 24.82944 | E34: =E29*Inputs!$B$106 -> 96.834816 | F34: =F29*Inputs!$B$106 -> 232.40356 | G34: =G29*Inputs!$B$106 -> 445.44015
A35: Value-share operating contribution | C35: =C29-C30-C32-C33-C34 -> 0 | D35: =D29-D30-D32-D33-D34 -> -157.25312 | E35: =E29-E30-E32-E33-E34 -> -613.28717 | F35: =F29-F30-F32-F33-F34 -> -1471.8892 | G35: =G29-G30-G32-G33-G34 -> -2821.121
A36: Value created as % of $40T knowledge-work pool | C36: =IFERROR(C27/Inputs!$B$27,0) -> 0 | D36: =IFERROR(D27/Inputs!$B$27,0) -> 4.13824e-05 | E36: =IFERROR(E27/Inputs!$B$27,0) -> 0.00016139136 | F36: =IFERROR(F27/Inputs!$B$27,0) -> 0.00038733926 | G36: =IFERROR(G27/Inputs!$B$27,0) -> 0.00074240026
A37: Value-share capital spending (per selected basis) | C37: =CHOOSE(Inputs!$B$35,C31*Inputs!B$55,C29*Inputs!$B$36,0) -> 0 | D37: =CHOOSE(Inputs!$B$35,D31*Inputs!C$55,D29*Inputs!$B$36,0) -> -1.655296 | E37: =CHOOSE(Inputs!$B$35,E31*Inputs!D$55,E29*Inputs!$B$36,0) -> -8.069568 | F37: =CHOOSE(Inputs!$B$35,F31*Inputs!E$55,F29*Inputs!$B$36,0) -> -19.366963 | G37: =CHOOSE(Inputs!$B$35,G31*Inputs!F$55,G29*Inputs!$B$36,0) -> -37.120013
A38: Value-share collection timing (working capital) | C38: 0 | D38: =-(D29-C29)*Inputs!$B$34/365 -> 0 | E38: =-(E29-D29)*Inputs!$B$34/365 -> 0 | F38: =-(F29-E29)*Inputs!$B$34/365 -> 0 | G38: =-(G29-F29)*Inputs!$B$34/365 -> 0
A40: Prepaid compute roll-forward (cash paid ahead of use)
A41: Prepaid balance, opening | C41: 0 | D41: =C46 -> 0 | E41: =D46 -> 0 | F41: =E46 -> 0 | G41: =F46 -> 0
A42: Prepayment paid (start of year) | C42: 0 | D42: =Inputs!$B$92 -> 0 | E42: 0 | F42: 0 | G42: 0
A43: Scheduled credits available (cumulative scheduled less used) | C43: =MAX(0,0) -> 0 | D43: =MAX(0,0) -> 0 | E43: =MAX(0,$D$42/Inputs!$B$40*MIN(1,Inputs!$B$40)-SUM($C45:D45)) -> 0 | F43: =MAX(0,$D$42/Inputs!$B$40*MIN(2,Inputs!$B$40)-SUM($C45:E45)) -> 0 | G43: =MAX(0,$D$42/Inputs!$B$40*MIN(3,Inputs!$B$40)-SUM($C45:F45)) -> 0
A44: Eligible compute charges this year | C44: =C10*Inputs!$B$39 -> 26666 | D44: =D10*Inputs!$B$39 -> 42665.6 | E44: =E10*Inputs!$B$39 -> 55465.28 | F44: =F10*Inputs!$B$39 -> 66558.336 | G44: =G10*Inputs!$B$39 -> 76542.086
...

Sheet Base
A1: Base — projections, cash and valuation ($ millions except per share)
A2: 2026E = H1 2026 actual + Q3 2026 implied + assumed Q4. Compute is forecast as cash spending (hosting, leases and owned capacity all treated as paid when expensed); the S-1 gives no payment schedule.
A4: Core business: income statement | B4: 2025A | C4: 2026E | D4: 2027E | E4: 2028E | F4: 2029E | G4: 2030E
A5: Revenue | B5: =Historicals!D35 -> 4585 | C5: =Historicals!F35+(Inputs!$B$5+Inputs!$C$60) -> 54228 | D5: =C5*(1+Inputs!$C$62) -> 108456 | E5: =D5*(1+Inputs!$C$63) -> 168106.8 | F5: =E5*(1+Inputs!$C$64) -> 226944.18 | G5: =F5*(1+Inputs!$C$65) -> 283680.22
A6: Growth | C6: =IFERROR(C5/B5-1,0) -> 10.827263 | D6: =IFERROR(D5/C5-1,0) -> 1 | E6: =IFERROR(E5/D5-1,0) -> 0.55 | F6: =IFERROR(F5/E5-1,0) -> 0.35 | G6: =IFERROR(G5/F5-1,0) -> 0.25
A7: Subscription revenue | B7: =Historicals!D51 -> 789 | C7: =Historicals!F51+(Inputs!$B$5+Inputs!$C$60)*Historicals!F51/Historicals!F35 -> 10728.393 | D7: =D5*Inputs!$C$61 -> 21691.2 | E7: =E5*Inputs!$C$61 -> 33621.36 | F7: =F5*Inputs!$C$61 -> 45388.836 | G7: =G5*Inputs!$C$61 -> 56736.045
A8: Consumption revenue | B8: =B5-B7 -> 3796 | C8: =C5-C7 -> 43499.607 | D8: =D5-D7 -> 86764.8 | E8: =E5-E7 -> 134485.44 | F8: =F5-F7 -> 181555.34 | G8: =G5-G7 -> 226944.18
A10: Compute and infrastructure | B10: =Historicals!D36 -> 7326 | C10: =Historicals!F36+(Inputs!$B$5+Inputs!$C$60)*Inputs!$C$66 -> 26018.9 | D10: =C10*(1+Inputs!$C$67) -> 44232.13 | E10: =D10*(1+Inputs!$C$68) -> 64136.588 | F10: =E10*(1+Inputs!$C$69) -> 83377.565 | G10: =F10*(1+Inputs!$C$70) -> 100053.08
A11: Personnel (incl. stock comp) | B11: =Historicals!D37 -> 1839 | C11: =Historicals!F37+(Inputs!$B$5+Inputs!$C$60)*Historicals!G24 -> 9249.6455 | D11: =D5*Inputs!$C$71 -> 15183.84 | E11: =E5*Inputs!$C$72 -> 21853.884 | F11: =F5*Inputs!$C$73 -> 27233.302 | G11: =G5*Inputs!$C$74 -> 31204.825
A12: of which stock comp | B12: =Historicals!D49 -> 1158 | C12: =Historicals!F49+(Inputs!$B$5+Inputs!$C$60)*Historicals!G29 -> 6325.6198 | D12: =D5*Inputs!$C$75 -> 9761.04 | E12: =E5*Inputs!$C$76 -> 13448.544 | F12: =F5*Inputs!$C$77 -> 15886.093 | G12: =G5*Inputs!$C$78 -> 17020.814
A13: Sales, marketing & partner fees | B13: =Historicals!D39 -> 568 | C13: =Historicals!F39+(Inputs!$B$5+Inputs!$C$60)*Historicals!G25 -> 10178.486 | D13: =D5*Inputs!$C$79 -> 18437.52 | E13: =E5*Inputs!$C$80 -> 26897.088 | F13: =F5*Inputs!$C$81 -> 34041.627 | G13: =G5*Inputs!$C$82 -> 42552.034
A14: Other operating & administrative | B14: =Historicals!D40 -> 1412 | C14: =Historicals!F40+(Inputs!$B$5+Inputs!$C$60)*Historicals!G26 -> 5099.3918 | D14: =D5*Inputs!$C$83 -> 8676.48 | E14: =E5*Inputs!$C$84 -> 11767.476 | F14: =F5*Inputs!$C$85 -> 13616.651 | G14: =G5*Inputs!$C$86 -> 17020.814
A15: One-time items (2025 Bartz settlement; 2026 Q3 donation-matching charge) | B15: =Historicals!D38 -> 1500 | C15: =Inputs!$B$37 -> 2000 | D15: 0 | E15: 0 | F15: 0 | G15: 0
A16: Total operating expenses | B16: =B10+B11+B13+B14+B15 -> 12645 | C16: =C10+C11+C13+C14+C15 -> 52546.424 | D16: =D10+D11+D13+D14+D15 -> 86529.97 | E16: =E10+E11+E13+E14+E15 -> 124655.04 | F16: =F10+F11+F13+F14+F15 -> 158269.14 | G16: =G10+G11+G13+G14+G15 -> 190830.75
A17: Operating income before depreciation of new owned capacity | B17: =B5-B16 -> -8060 | C17: =C5-C16 -> 1681.5763 | D17: =D5-D16 -> 21926.03 | E17: =E5-E16 -> 43451.764 | F17: =F5-F16 -> 68675.036 | G17: =G5-G16 -> 92849.475
A18: Margin | B18: =IFERROR(B17/B5,0) -> -1.7579062 | C18: =IFERROR(C17/C5,0) -> 0.031009374 | D18: =IFERROR(D17/D5,0) -> 0.20216521 | E18: =IFERROR(E17/E5,0) -> 0.25847713 | F18: =IFERROR(F17/F5,0) -> 0.30260761 | G18: =IFERROR(G17/G5,0) -> 0.3273033
A19: Compute % of revenue | B19: =IFERROR(B10/B5,0) -> 1.597819 | C19: =IFERROR(C10/C5,0) -> 0.47980564 | D19: =IFERROR(D10/D5,0) -> 0.40783479 | E19: =IFERROR(E10/E5,0) -> 0.38152287 | F19: =IFERROR(F10/F5,0) -> 0.36739239 | G19: =IFERROR(G10/G5,0) -> 0.3526967
A20: Non-cash donation-matching charges (incl. in costs above) | C20: =Historicals!$B$78+Inputs!$B$37 -> 2126 | D20: 0 | E20: 0 | F20: 0 | G20: 0
A21: Discount factor to end 2026 | D21: =1/(1+Inputs!$B$19+Inputs!$C$89)^1 -> 0.89285714 | E21: =1/(1+Inputs!$B$19+Inputs!$C$89)^2 -> 0.79719388 | F21: =1/(1+Inputs!$B$19+Inputs!$C$89)^3 -> 0.71178025 | G21: =1/(1+Inputs!$B$19+Inputs!$C$89)^4 -> 0.63551808
A23: Third business line: value-share partnerships (hypothetical)
A24: Share of core revenue base under value-share | C24: 0 | D24: =Inputs!$C$97 -> 0.02 | E24: =Inputs!$C$98 -> 0.05 | F24: =Inputs!$C$99 -> 0.1 | G24: =Inputs!$C$100 -> 0.15
A25: Revenue base moved to value-share | C25: =C5*C24 -> 0 | D25: =D5*D24 -> 2169.12 | E25: =E5*E24 -> 8405.34 | F25: =F5*F24 -> 22694.418 | G25: =G5*G24 -> 42552.034
A26: Value created per $1 of Claude spend | C26: =Inputs!$C$101 -> 8 | D26: =Inputs!$C$101 -> 8 | E26: =Inputs!$C$101 -> 8 | F26: =Inputs!$C$101 -> 8 | G26: =Inputs!$C$101 -> 8
A27: Economic value created for partners | C27: =C25*C26 -> 0 | D27: =D25*D26 -> 17352.96 | E27: =E25*E26 -> 67242.72 | F27: =F25*F26 -> 181555.34 | G27: =G25*G26 -> 340416.27
A28: Anthropic's cut | C28: =Inputs!$C$102 -> 0.15 | D28: =Inputs!$C$102 -> 0.15 | E28: =Inputs!$C$102 -> 0.15 | F28: =Inputs!$C$102 -> 0.15 | G28: =Inputs!$C$102 -> 0.15
A29: Value-share revenue (gross) | C29: =C27*C28 -> 0 | D29: =D27*D28 -> 2602.944 | E29: =E27*E28 -> 10086.408 | F29: =F27*F28 -> 27233.302 | G29: =G27*G28 -> 51062.44
A30: Token revenue given up | C30: =C25*Inputs!$C$103 -> 0 | D30: =D25*Inputs!$C$103 -> 650.736 | E30: =E25*Inputs!$C$103 -> 2521.602 | F30: =F25*Inputs!$C$103 -> 6808.3254 | G30: =G25*Inputs!$C$103 -> 12765.61
A31: Net new revenue | C31: =C29-C30 -> 0 | D31: =D29-D30 -> 1952.208 | E31: =E29-E30 -> 7564.806 | F31: =F29-F30 -> 20424.976 | G31: =G29-G30 -> 38296.83
A32: Delivery cost | C32: =C29*Inputs!$C$104 -> 0 | D32: =D29*Inputs!$C$104 -> 520.5888 | E32: =E29*Inputs!$C$104 -> 2017.2816 | F32: =F29*Inputs!$C$104 -> 5446.6603 | G32: =G29*Inputs!$C$104 -> 10212.488
A33: Extra compute | C33: =C29*Inputs!$C$105 -> 0 | D33: =D29*Inputs!$C$105 -> 390.4416 | E33: =E29*Inputs!$C$105 -> 1512.9612 | F33: =F29*Inputs!$C$105 -> 4084.9952 | G33: =G29*Inputs!$C$105 -> 7659.3661
A34: Selling, partner fees & overhead | C34: =C29*Inputs!$C$106 -> 0 | D34: =D29*Inputs!$C$106 -> 260.2944 | E34: =E29*Inputs!$C$106 -> 1008.6408 | F34: =F29*Inputs!$C$106 -> 2723.3302 | G34: =G29*Inputs!$C$106 -> 5106.2441
A35: Value-share operating contribution | C35: =C29-C30-C32-C33-C34 -> 0 | D35: =D29-D30-D32-D33-D34 -> 780.8832 | E35: =E29-E30-E32-E33-E34 -> 3025.9224 | F35: =F29-F30-F32-F33-F34 -> 8169.9905 | G35: =G29-G30-G32-G33-G34 -> 15318.732
A36: Value created as % of $40T knowledge-work pool | C36: =IFERROR(C27/Inputs!$B$27,0) -> 0 | D36: =IFERROR(D27/Inputs!$B$27,0) -> 0.000433824 | E36: =IFERROR(E27/Inputs!$B$27,0) -> 0.001681068 | F36: =IFERROR(F27/Inputs!$B$27,0) -> 0.0045388836 | G36: =IFERROR(G27/Inputs!$B$27,0) -> 0.0085104067
A37: Value-share capital spending (per selected basis) | C37: =CHOOSE(Inputs!$B$35,C31*Inputs!B$55,C29*Inputs!$B$36,0) -> 0 | D37: =CHOOSE(Inputs!$B$35,D31*Inputs!C$55,D29*Inputs!$B$36,0) -> 78.08832 | E37: =CHOOSE(Inputs!$B$35,E31*Inputs!D$55,E29*Inputs!$B$36,0) -> 378.2403 | F37: =CHOOSE(Inputs!$B$35,F31*Inputs!E$55,F29*Inputs!$B$36,0) -> 1021.2488 | G37: =CHOOSE(Inputs!$B$35,G31*Inputs!F$55,G29*Inputs!$B$36,0) -> 1914.8415
A38: Value-share collection timing (working capital) | C38: 0 | D38: =-(D29-C29)*Inputs!$B$34/365 -> 0 | E38: =-(E29-D29)*Inputs!$B$34/365 -> 0 | F38: =-(F29-E29)*Inputs!$B$34/365 -> 0 | G38: =-(G29-F29)*Inputs!$B$34/365 -> 0
A40: Prepaid compute roll-forward (cash paid ahead of use)
A41: Prepaid balance, opening | C41: 0 | D41: =C46 -> 0 | E41: =D46 -> 0 | F41: =E46 -> 0 | G41: =F46 -> 0
A42: Prepayment paid (start of year) | C42: 0 | D42: =Inputs!$C$92 -> 0 | E42: 0 | F42: 0 | G42: 0
A43: Scheduled credits available (cumulative scheduled less used) | C43: =MAX(0,0) -> 0 | D43: =MAX(0,0) -> 0 | E43: =MAX(0,$D$42/Inputs!$B$40*MIN(1,Inputs!$B$40)-SUM($C45:D45)) -> 0 | F43: =MAX(0,$D$42/Inputs!$B$40*MIN(2,Inputs!$B$40)-SUM($C45:E45)) -> 0 | G43: =MAX(0,$D$42/Inputs!$B$40*MIN(3,Inputs!$B$40)-SUM($C45:F45)) -> 0
A44: Eligible compute charges this year | C44: =C10*Inputs!$B$39 -> 26018.9 | D44: =D10*Inputs!$B$39 -> 44232.13 | E44: =E10*Inputs!$B$39 -> 64136.588 | F44: =F10*Inputs!$B$39 -> 83377.565 | G44: =G10*Inputs!$B$39 -> 100053.08
...

Sheet Bull
A1: Bull — projections, cash and valuation ($ millions except per share)
A2: 2026E = H1 2026 actual + Q3 2026 implied + assumed Q4. Compute is forecast as cash spending (hosting, leases and owned capacity all treated as paid when expensed); the S-1 gives no payment schedule.
A4: Core business: income statement | B4: 2025A | C4: 2026E | D4: 2027E | E4: 2028E | F4: 2029E | G4: 2030E
A5: Revenue | B5: =Historicals!D35 -> 4585 | C5: =Historicals!F35+(Inputs!$B$5+Inputs!$D$60) -> 57228 | D5: =C5*(1+Inputs!$D$62) -> 143070 | E5: =D5*(1+Inputs!$D$63) -> 257526 | F5: =E5*(1+Inputs!$D$64) -> 386289 | G5: =F5*(1+Inputs!$D$65) -> 521490.15
A6: Growth | C6: =IFERROR(C5/B5-1,0) -> 11.48157 | D6: =IFERROR(D5/C5-1,0) -> 1.5 | E6: =IFERROR(E5/D5-1,0) -> 0.8 | F6: =IFERROR(F5/E5-1,0) -> 0.5 | G6: =IFERROR(G5/F5-1,0) -> 0.35
A7: Subscription revenue | B7: =Historicals!D51 -> 789 | C7: =Historicals!F51+(Inputs!$B$5+Inputs!$D$60)*Historicals!F51/Historicals!F35 -> 11321.909 | D7: =D5*Inputs!$D$61 -> 25752.6 | E7: =E5*Inputs!$D$61 -> 46354.68 | F7: =F5*Inputs!$D$61 -> 69532.02 | G7: =G5*Inputs!$D$61 -> 93868.227
A8: Consumption revenue | B8: =B5-B7 -> 3796 | C8: =C5-C7 -> 45906.091 | D8: =D5-D7 -> 117317.4 | E8: =E5-E7 -> 211171.32 | F8: =F5-F7 -> 316756.98 | G8: =G5-G7 -> 427621.92
A10: Compute and infrastructure | B10: =Historicals!D36 -> 7326 | C10: =Historicals!F36+(Inputs!$B$5+Inputs!$D$60)*Inputs!$D$66 -> 26140.64 | D10: =C10*(1+Inputs!$D$67) -> 49667.216 | E10: =D10*(1+Inputs!$D$68) -> 79467.546 | F10: =E10*(1+Inputs!$D$69) -> 115227.94 | G10: =F10*(1+Inputs!$D$70) -> 149796.32
A11: Personnel (incl. stock comp) | B11: =Historicals!D37 -> 1839 | C11: =Historicals!F37+(Inputs!$B$5+Inputs!$D$60)*Historicals!G24 -> 9731.7745 | D11: =D5*Inputs!$D$71 -> 18599.1 | E11: =E5*Inputs!$D$72 -> 30903.12 | F11: =F5*Inputs!$D$73 -> 42491.79 | G11: =G5*Inputs!$D$74 -> 52149.015
A12: of which stock comp | B12: =Historicals!D49 -> 1158 | C12: =Historicals!F49+(Inputs!$B$5+Inputs!$D$60)*Historicals!G29 -> 6653.0106 | D12: =D5*Inputs!$D$75 -> 11445.6 | E12: =E5*Inputs!$D$76 -> 18026.82 | F12: =F5*Inputs!$D$77 -> 23177.34 | G12: =G5*Inputs!$D$78 -> 26074.507
A13: Sales, marketing & partner fees | B13: =Historicals!D39 -> 568 | C13: =Historicals!F39+(Inputs!$B$5+Inputs!$D$60)*Historicals!G25 -> 10732.792 | D13: =D5*Inputs!$D$79 -> 22891.2 | E13: =E5*Inputs!$D$80 -> 38628.9 | F13: =F5*Inputs!$D$81 -> 54080.46 | G13: =G5*Inputs!$D$82 -> 67793.72
A14: Other operating & administrative | B14: =Historicals!D40 -> 1412 | C14: =Historicals!F40+(Inputs!$B$5+Inputs!$D$60)*Historicals!G26 -> 5367.0681 | D14: =D5*Inputs!$D$83 -> 10014.9 | E14: =E5*Inputs!$D$84 -> 15451.56 | F14: =F5*Inputs!$D$85 -> 19314.45 | G14: =G5*Inputs!$D$86 -> 26074.507
A15: One-time items (2025 Bartz settlement; 2026 Q3 donation-matching charge) | B15: =Historicals!D38 -> 1500 | C15: =Inputs!$B$37 -> 2000 | D15: 0 | E15: 0 | F15: 0 | G15: 0
A16: Total operating expenses | B16: =B10+B11+B13+B14+B15 -> 12645 | C16: =C10+C11+C13+C14+C15 -> 53972.274 | D16: =D10+D11+D13+D14+D15 -> 101172.42 | E16: =E10+E11+E13+E14+E15 -> 164451.13 | F16: =F10+F11+F13+F14+F15 -> 231114.64 | G16: =G10+G11+G13+G14+G15 -> 295813.57
A17: Operating income before depreciation of new owned capacity | B17: =B5-B16 -> -8060 | C17: =C5-C16 -> 3255.7256 | D17: =D5-D16 -> 41897.584 | E17: =E5-E16 -> 93074.874 | F17: =F5-F16 -> 155174.36 | G17: =G5-G16 -> 225676.58
A18: Margin | B18: =IFERROR(B17/B5,0) -> -1.7579062 | C18: =IFERROR(C17/C5,0) -> 0.05689043 | D18: =IFERROR(D17/D5,0) -> 0.29284675 | E18: =IFERROR(E17/E5,0) -> 0.36141933 | F18: =IFERROR(F17/F5,0) -> 0.40170535 | G18: =IFERROR(G17/G5,0) -> 0.4327533
A19: Compute % of revenue | B19: =IFERROR(B10/B5,0) -> 1.597819 | C19: =IFERROR(C10/C5,0) -> 0.4567806 | D19: =IFERROR(D10/D5,0) -> 0.34715325 | E19: =IFERROR(E10/E5,0) -> 0.30858067 | F19: =IFERROR(F10/F5,0) -> 0.29829465 | G19: =IFERROR(G10/G5,0) -> 0.2872467
A20: Non-cash donation-matching charges (incl. in costs above) | C20: =Historicals!$B$78+Inputs!$B$37 -> 2126 | D20: 0 | E20: 0 | F20: 0 | G20: 0
A21: Discount factor to end 2026 | D21: =1/(1+Inputs!$B$19+Inputs!$D$89)^1 -> 0.89285714 | E21: =1/(1+Inputs!$B$19+Inputs!$D$89)^2 -> 0.79719388 | F21: =1/(1+Inputs!$B$19+Inputs!$D$89)^3 -> 0.71178025 | G21: =1/(1+Inputs!$B$19+Inputs!$D$89)^4 -> 0.63551808
A23: Third business line: value-share partnerships (hypothetical)
A24: Share of core revenue base under value-share | C24: 0 | D24: =Inputs!$D$97 -> 0.04 | E24: =Inputs!$D$98 -> 0.1 | F24: =Inputs!$D$99 -> 0.18 | G24: =Inputs!$D$100 -> 0.25
A25: Revenue base moved to value-share | C25: =C5*C24 -> 0 | D25: =D5*D24 -> 5722.8 | E25: =E5*E24 -> 25752.6 | F25: =F5*F24 -> 69532.02 | G25: =G5*G24 -> 130372.54
A26: Value created per $1 of Claude spend | C26: =Inputs!$D$101 -> 12 | D26: =Inputs!$D$101 -> 12 | E26: =Inputs!$D$101 -> 12 | F26: =Inputs!$D$101 -> 12 | G26: =Inputs!$D$101 -> 12
A27: Economic value created for partners | C27: =C25*C26 -> 0 | D27: =D25*D26 -> 68673.6 | E27: =E25*E26 -> 309031.2 | F27: =F25*F26 -> 834384.24 | G27: =G25*G26 -> 1564470.4
A28: Anthropic's cut | C28: =Inputs!$D$102 -> 0.2 | D28: =Inputs!$D$102 -> 0.2 | E28: =Inputs!$D$102 -> 0.2 | F28: =Inputs!$D$102 -> 0.2 | G28: =Inputs!$D$102 -> 0.2
A29: Value-share revenue (gross) | C29: =C27*C28 -> 0 | D29: =D27*D28 -> 13734.72 | E29: =E27*E28 -> 61806.24 | F29: =F27*F28 -> 166876.85 | G29: =G27*G28 -> 312894.09
A30: Token revenue given up | C30: =C25*Inputs!$D$103 -> 0 | D30: =D25*Inputs!$D$103 -> 1144.56 | E30: =E25*Inputs!$D$103 -> 5150.52 | F30: =F25*Inputs!$D$103 -> 13906.404 | G30: =G25*Inputs!$D$103 -> 26074.507
A31: Net new revenue | C31: =C29-C30 -> 0 | D31: =D29-D30 -> 12590.16 | E31: =E29-E30 -> 56655.72 | F31: =F29-F30 -> 152970.44 | G31: =G29-G30 -> 286819.58
A32: Delivery cost | C32: =C29*Inputs!$D$104 -> 0 | D32: =D29*Inputs!$D$104 -> 2060.208 | E32: =E29*Inputs!$D$104 -> 9270.936 | F32: =F29*Inputs!$D$104 -> 25031.527 | G32: =G29*Inputs!$D$104 -> 46934.113
A33: Extra compute | C33: =C29*Inputs!$D$105 -> 0 | D33: =D29*Inputs!$D$105 -> 1373.472 | E33: =E29*Inputs!$D$105 -> 6180.624 | F33: =F29*Inputs!$D$105 -> 16687.685 | G33: =G29*Inputs!$D$105 -> 31289.409
A34: Selling, partner fees & overhead | C34: =C29*Inputs!$D$106 -> 0 | D34: =D29*Inputs!$D$106 -> 1098.7776 | E34: =E29*Inputs!$D$106 -> 4944.4992 | F34: =F29*Inputs!$D$106 -> 13350.148 | G34: =G29*Inputs!$D$106 -> 25031.527
A35: Value-share operating contribution | C35: =C29-C30-C32-C33-C34 -> 0 | D35: =D29-D30-D32-D33-D34 -> 8057.7024 | E35: =E29-E30-E32-E33-E34 -> 36259.661 | F35: =F29-F30-F32-F33-F34 -> 97901.084 | G35: =G29-G30-G32-G33-G34 -> 183564.53
A36: Value created as % of $40T knowledge-work pool | C36: =IFERROR(C27/Inputs!$B$27,0) -> 0 | D36: =IFERROR(D27/Inputs!$B$27,0) -> 0.00171684 | E36: =IFERROR(E27/Inputs!$B$27,0) -> 0.00772578 | F36: =IFERROR(F27/Inputs!$B$27,0) -> 0.020859606 | G36: =IFERROR(G27/Inputs!$B$27,0) -> 0.039111761
A37: Value-share capital spending (per selected basis) | C37: =CHOOSE(Inputs!$B$35,C31*Inputs!B$55,C29*Inputs!$B$36,0) -> 0 | D37: =CHOOSE(Inputs!$B$35,D31*Inputs!C$55,D29*Inputs!$B$36,0) -> 503.6064 | E37: =CHOOSE(Inputs!$B$35,E31*Inputs!D$55,E29*Inputs!$B$36,0) -> 2832.786 | F37: =CHOOSE(Inputs!$B$35,F31*Inputs!E$55,F29*Inputs!$B$36,0) -> 7648.5222 | G37: =CHOOSE(Inputs!$B$35,G31*Inputs!F$55,G29*Inputs!$B$36,0) -> 14340.979
A38: Value-share collection timing (working capital) | C38: 0 | D38: =-(D29-C29)*Inputs!$B$34/365 -> 0 | E38: =-(E29-D29)*Inputs!$B$34/365 -> 0 | F38: =-(F29-E29)*Inputs!$B$34/365 -> 0 | G38: =-(G29-F29)*Inputs!$B$34/365 -> 0
A40: Prepaid compute roll-forward (cash paid ahead of use)
A41: Prepaid balance, opening | C41: 0 | D41: =C46 -> 0 | E41: =D46 -> 0 | F41: =E46 -> 0 | G41: =F46 -> 0
A42: Prepayment paid (start of year) | C42: 0 | D42: =Inputs!$D$92 -> 0 | E42: 0 | F42: 0 | G42: 0
A43: Scheduled credits available (cumulative scheduled less used) | C43: =MAX(0,0) -> 0 | D43: =MAX(0,0) -> 0 | E43: =MAX(0,$D$42/Inputs!$B$40*MIN(1,Inputs!$B$40)-SUM($C45:D45)) -> 0 | F43: =MAX(0,$D$42/Inputs!$B$40*MIN(2,Inputs!$B$40)-SUM($C45:E45)) -> 0 | G43: =MAX(0,$D$42/Inputs!$B$40*MIN(3,Inputs!$B$40)-SUM($C45:F45)) -> 0
A44: Eligible compute charges this year | C44: =C10*Inputs!$B$39 -> 26140.64 | D44: =D10*Inputs!$B$39 -> 49667.216 | E44: =E10*Inputs!$B$39 -> 79467.546 | F44: =F10*Inputs!$B$39 -> 115227.94 | G44: =G10*Inputs!$B$39 -> 149796.32
...

Sheet S1
A1: S1 Flat revenue — projections, cash and valuation ($ millions except per share)
A2: 2026E = H1 2026 actual + Q3 2026 implied + assumed Q4. Compute is forecast as cash spending (hosting, leases and owned capacity all treated as paid when expensed); the S-1 gives no payment schedule.
A4: Core business: income statement | B4: 2025A | C4: 2026E | D4: 2027E | E4: 2028E | F4: 2029E | G4: 2030E
A5: Revenue | B5: =Historicals!D35 -> 4585 | C5: =Historicals!F35+(Inputs!$B$5+Inputs!$G$60) -> 54228 | D5: =C5*(1+Inputs!$G$62) -> 54228 | E5: =D5*(1+Inputs!$G$63) -> 54228 | F5: =E5*(1+Inputs!$G$64) -> 54228 | G5: =F5*(1+Inputs!$G$65) -> 54228
A6: Growth | C6: =IFERROR(C5/B5-1,0) -> 10.827263 | D6: =IFERROR(D5/C5-1,0) -> 0 | E6: =IFERROR(E5/D5-1,0) -> 0 | F6: =IFERROR(F5/E5-1,0) -> 0 | G6: =IFERROR(G5/F5-1,0) -> 0
A7: Subscription revenue | B7: =Historicals!D51 -> 789 | C7: =Historicals!F51+(Inputs!$B$5+Inputs!$G$60)*Historicals!F51/Historicals!F35 -> 10728.393 | D7: =D5*Inputs!$G$61 -> 10845.6 | E7: =E5*Inputs!$G$61 -> 10845.6 | F7: =F5*Inputs!$G$61 -> 10845.6 | G7: =G5*Inputs!$G$61 -> 10845.6
A8: Consumption revenue | B8: =B5-B7 -> 3796 | C8: =C5-C7 -> 43499.607 | D8: =D5-D7 -> 43382.4 | E8: =E5-E7 -> 43382.4 | F8: =F5-F7 -> 43382.4 | G8: =G5-G7 -> 43382.4
A10: Compute and infrastructure | B10: =Historicals!D36 -> 7326 | C10: =Historicals!F36+(Inputs!$B$5+Inputs!$G$60)*Inputs!$G$66 -> 26018.9 | D10: =C10*(1+Inputs!$G$67) -> 44232.13 | E10: =D10*(1+Inputs!$G$68) -> 64136.588 | F10: =E10*(1+Inputs!$G$69) -> 83377.565 | G10: =F10*(1+Inputs!$G$70) -> 100053.08
A11: Personnel (incl. stock comp) | B11: =Historicals!D37 -> 1839 | C11: =Historicals!F37+(Inputs!$B$5+Inputs!$G$60)*Historicals!G24 -> 9249.6455 | D11: =D5*Inputs!$G$71 -> 7591.92 | E11: =E5*Inputs!$G$72 -> 7049.64 | F11: =F5*Inputs!$G$73 -> 6507.36 | G11: =G5*Inputs!$G$74 -> 5965.08
A12: of which stock comp | B12: =Historicals!D49 -> 1158 | C12: =Historicals!F49+(Inputs!$B$5+Inputs!$G$60)*Historicals!G29 -> 6325.6198 | D12: =D5*Inputs!$G$75 -> 4880.52 | E12: =E5*Inputs!$G$76 -> 4338.24 | F12: =F5*Inputs!$G$77 -> 3795.96 | G12: =G5*Inputs!$G$78 -> 3253.68
A13: Sales, marketing & partner fees | B13: =Historicals!D39 -> 568 | C13: =Historicals!F39+(Inputs!$B$5+Inputs!$G$60)*Historicals!G25 -> 10178.486 | D13: =D5*Inputs!$G$79 -> 9218.76 | E13: =E5*Inputs!$G$80 -> 8676.48 | F13: =F5*Inputs!$G$81 -> 8134.2 | G13: =G5*Inputs!$G$82 -> 8134.2
A14: Other operating & administrative | B14: =Historicals!D40 -> 1412 | C14: =Historicals!F40+(Inputs!$B$5+Inputs!$G$60)*Historicals!G26 -> 5099.3918 | D14: =D5*Inputs!$G$83 -> 4338.24 | E14: =E5*Inputs!$G$84 -> 3795.96 | F14: =F5*Inputs!$G$85 -> 3253.68 | G14: =G5*Inputs!$G$86 -> 3253.68
A15: One-time items (2025 Bartz settlement; 2026 Q3 donation-matching charge) | B15: =Historicals!D38 -> 1500 | C15: =Inputs!$B$37 -> 2000 | D15: 0 | E15: 0 | F15: 0 | G15: 0
A16: Total operating expenses | B16: =B10+B11+B13+B14+B15 -> 12645 | C16: =C10+C11+C13+C14+C15 -> 52546.424 | D16: =D10+D11+D13+D14+D15 -> 65381.05 | E16: =E10+E11+E13+E14+E15 -> 83658.668 | F16: =F10+F11+F13+F14+F15 -> 101272.81 | G16: =G10+G11+G13+G14+G15 -> 117406.04
A17: Operating income before depreciation of new owned capacity | B17: =B5-B16 -> -8060 | C17: =C5-C16 -> 1681.5763 | D17: =D5-D16 -> -11153.05 | E17: =E5-E16 -> -29430.668 | F17: =F5-F16 -> -47044.805 | G17: =G5-G16 -> -63178.038
A18: Margin | B18: =IFERROR(B17/B5,0) -> -1.7579062 | C18: =IFERROR(C17/C5,0) -> 0.031009374 | D18: =IFERROR(D17/D5,0) -> -0.20566958 | E18: =IFERROR(E17/E5,0) -> -0.54272089 | F18: =IFERROR(F17/F5,0) -> -0.86753716 | G18: =IFERROR(G17/G5,0) -> -1.1650446
A19: Compute % of revenue | B19: =IFERROR(B10/B5,0) -> 1.597819 | C19: =IFERROR(C10/C5,0) -> 0.47980564 | D19: =IFERROR(D10/D5,0) -> 0.81566958 | E19: =IFERROR(E10/E5,0) -> 1.1827209 | F19: =IFERROR(F10/F5,0) -> 1.5375372 | G19: =IFERROR(G10/G5,0) -> 1.8450446
A20: Non-cash donation-matching charges (incl. in costs above) | C20: =Historicals!$B$78+Inputs!$B$37 -> 2126 | D20: 0 | E20: 0 | F20: 0 | G20: 0
A21: Discount factor to end 2026 | D21: =1/(1+Inputs!$B$19+Inputs!$G$89)^1 -> 0.89285714 | E21: =1/(1+Inputs!$B$19+Inputs!$G$89)^2 -> 0.79719388 | F21: =1/(1+Inputs!$B$19+Inputs!$G$89)^3 -> 0.71178025 | G21: =1/(1+Inputs!$B$19+Inputs!$G$89)^4 -> 0.63551808
A23: Third business line: value-share partnerships (hypothetical)
A24: Share of core revenue base under value-share | C24: 0 | D24: =Inputs!$C$97 -> 0.02 | E24: =Inputs!$C$98 -> 0.05 | F24: =Inputs!$C$99 -> 0.1 | G24: =Inputs!$C$100 -> 0.15
A25: Revenue base moved to value-share | C25: =C5*C24 -> 0 | D25: =D5*D24 -> 1084.56 | E25: =E5*E24 -> 2711.4 | F25: =F5*F24 -> 5422.8 | G25: =G5*G24 -> 8134.2
A26: Value created per $1 of Claude spend | C26: =Inputs!$C$101 -> 8 | D26: =Inputs!$C$101 -> 8 | E26: =Inputs!$C$101 -> 8 | F26: =Inputs!$C$101 -> 8 | G26: =Inputs!$C$101 -> 8
A27: Economic value created for partners | C27: =C25*C26 -> 0 | D27: =D25*D26 -> 8676.48 | E27: =E25*E26 -> 21691.2 | F27: =F25*F26 -> 43382.4 | G27: =G25*G26 -> 65073.6
A28: Anthropic's cut | C28: =Inputs!$C$102 -> 0.15 | D28: =Inputs!$C$102 -> 0.15 | E28: =Inputs!$C$102 -> 0.15 | F28: =Inputs!$C$102 -> 0.15 | G28: =Inputs!$C$102 -> 0.15
A29: Value-share revenue (gross) | C29: =C27*C28 -> 0 | D29: =D27*D28 -> 1301.472 | E29: =E27*E28 -> 3253.68 | F29: =F27*F28 -> 6507.36 | G29: =G27*G28 -> 9761.04
A30: Token revenue given up | C30: =C25*Inputs!$C$103 -> 0 | D30: =D25*Inputs!$C$103 -> 325.368 | E30: =E25*Inputs!$C$103 -> 813.42 | F30: =F25*Inputs!$C$103 -> 1626.84 | G30: =G25*Inputs!$C$103 -> 2440.26
A31: Net new revenue | C31: =C29-C30 -> 0 | D31: =D29-D30 -> 976.104 | E31: =E29-E30 -> 2440.26 | F31: =F29-F30 -> 4880.52 | G31: =G29-G30 -> 7320.78
A32: Delivery cost | C32: =C29*Inputs!$C$104 -> 0 | D32: =D29*Inputs!$C$104 -> 260.2944 | E32: =E29*Inputs!$C$104 -> 650.736 | F32: =F29*Inputs!$C$104 -> 1301.472 | G32: =G29*Inputs!$C$104 -> 1952.208
A33: Extra compute | C33: =C29*Inputs!$C$105 -> 0 | D33: =D29*Inputs!$C$105 -> 195.2208 | E33: =E29*Inputs!$C$105 -> 488.052 | F33: =F29*Inputs!$C$105 -> 976.104 | G33: =G29*Inputs!$C$105 -> 1464.156
A34: Selling, partner fees & overhead | C34: =C29*Inputs!$C$106 -> 0 | D34: =D29*Inputs!$C$106 -> 130.1472 | E34: =E29*Inputs!$C$106 -> 325.368 | F34: =F29*Inputs!$C$106 -> 650.736 | G34: =G29*Inputs!$C$106 -> 976.104
A35: Value-share operating contribution | C35: =C29-C30-C32-C33-C34 -> 0 | D35: =D29-D30-D32-D33-D34 -> 390.4416 | E35: =E29-E30-E32-E33-E34 -> 976.104 | F35: =F29-F30-F32-F33-F34 -> 1952.208 | G35: =G29-G30-G32-G33-G34 -> 2928.312
A36: Value created as % of $40T knowledge-work pool | C36: =IFERROR(C27/Inputs!$B$27,0) -> 0 | D36: =IFERROR(D27/Inputs!$B$27,0) -> 0.000216912 | E36: =IFERROR(E27/Inputs!$B$27,0) -> 0.00054228 | F36: =IFERROR(F27/Inputs!$B$27,0) -> 0.00108456 | G36: =IFERROR(G27/Inputs!$B$27,0) -> 0.00162684
A37: Value-share capital spending (per selected basis) | C37: =CHOOSE(Inputs!$B$35,C31*Inputs!B$55,C29*Inputs!$B$36,0) -> 0 | D37: =CHOOSE(Inputs!$B$35,D31*Inputs!C$55,D29*Inputs!$B$36,0) -> 39.04416 | E37: =CHOOSE(Inputs!$B$35,E31*Inputs!D$55,E29*Inputs!$B$36,0) -> 122.013 | F37: =CHOOSE(Inputs!$B$35,F31*Inputs!E$55,F29*Inputs!$B$36,0) -> 244.026 | G37: =CHOOSE(Inputs!$B$35,G31*Inputs!F$55,G29*Inputs!$B$36,0) -> 366.039
A38: Value-share collection timing (working capital) | C38: 0 | D38: =-(D29-C29)*Inputs!$B$34/365 -> 0 | E38: =-(E29-D29)*Inputs!$B$34/365 -> 0 | F38: =-(F29-E29)*Inputs!$B$34/365 -> 0 | G38: =-(G29-F29)*Inputs!$B$34/365 -> 0
A40: Prepaid compute roll-forward (cash paid ahead of use)
A41: Prepaid balance, opening | C41: 0 | D41: =C46 -> 0 | E41: =D46 -> 0 | F41: =E46 -> 0 | G41: =F46 -> 0
A42: Prepayment paid (start of year) | C42: 0 | D42: =Inputs!$G$92 -> 0 | E42: 0 | F42: 0 | G42: 0
